<?xml version="1.0" encoding="utf-8"?>
<!-- =================================================================================== -->
<!-- |    This document was autogenerated by xacro from cupboard_drawers.urdf.xacro    | -->
<!-- |    EDITING THIS FILE BY HAND IS NOT RECOMMENDED                                 | -->
<!-- =================================================================================== -->
<robot name="cupboard_drawers" xmlns:xacro="http://www.ros.org/wiki/xacro">
  <link name="base_link"/>
  <link name="frame_back_wall">
    <contact>
      <lateral_friction value="1.0"/>
    </contact>
    <inertial>
      <origin rpy="0 0 0" xyz="0 0 0"/>
      <mass value="0.2"/>
      <inertia ixx="1" ixy="0" ixz="0" iyy="1" iyz="0" izz="1"/>
    </inertial>
    <visual>
      <origin rpy="0 0 0" xyz="0 0 0"/>
      <geometry>
        <box size="1.4 0.05 1.4"/>
      </geometry>
      <material name="white">
        <color rgba="1 1 1 1"/>
      </material>
    </visual>
    <collision>
      <origin rpy="0 0 0" xyz="0 0 0"/>
      <geometry>
        <box size="1.4 0.05 1.4"/>
      </geometry>
    </collision>
  </link>
  <link name="frame_bottom_wall">
    <contact>
      <lateral_friction value="1.0"/>
    </contact>
    <inertial>
      <origin rpy="0 0 0" xyz="0 0 0"/>
      <mass value="0.2"/>
      <inertia ixx="1" ixy="0" ixz="0" iyy="1" iyz="0" izz="1"/>
    </inertial>
    <visual>
      <origin rpy="0 0 0" xyz="0 0 0"/>
      <geometry>
        <box size="1.5 0.05 1.0"/>
      </geometry>
      <material name="white">
        <color rgba="1 1 1 1"/>
      </material>
    </visual>
    <collision>
      <origin rpy="0 0 0" xyz="0 0 0"/>
      <geometry>
        <box size="1.5 0.05 1.0"/>
      </geometry>
    </collision>
  </link>
  <joint name="frame_bottom_joint" type="fixed">
    <origin rpy="1.57079632679 0 0" xyz="0 -0.475 -0.725"/>
    <parent link="frame_back_wall"/>
    <child link="frame_bottom_wall"/>
  </joint>
  <link name="frame_left_wall">
    <contact>
      <lateral_friction value="1.0"/>
    </contact>
    <inertial>
      <origin rpy="0 0 0" xyz="0 0 0"/>
      <mass value="0.2"/>
      <inertia ixx="1" ixy="0" ixz="0" iyy="1" iyz="0" izz="1"/>
    </inertial>
    <visual>
      <origin rpy="0 0 0" xyz="0 0 0"/>
      <geometry>
        <box size="1.0 0.05 1.4"/>
      </geometry>
      <material name="white">
        <color rgba="1 1 1 1"/>
      </material>
    </visual>
    <collision>
      <origin rpy="0 0 0" xyz="0 0 0"/>
      <geometry>
        <box size="1.0 0.05 1.4"/>
      </geometry>
    </collision>
  </link>
  <joint name="frame_left_joint" type="fixed">
    <origin rpy="0 0 1.57079632679" xyz="-0.725 -0.475 0"/>
    <parent link="frame_back_wall"/>
    <child link="frame_left_wall"/>
  </joint>
  <link name="frame_right_wall">
    <contact>
      <lateral_friction value="1.0"/>
    </contact>
    <inertial>
      <origin rpy="0 0 0" xyz="0 0 0"/>
      <mass value="0.2"/>
      <inertia ixx="1" ixy="0" ixz="0" iyy="1" iyz="0" izz="1"/>
    </inertial>
    <visual>
      <origin rpy="0 0 0" xyz="0 0 0"/>
      <geometry>
        <box size="1.0 0.05 1.4"/>
      </geometry>
      <material name="white">
        <color rgba="1 1 1 1"/>
      </material>
    </visual>
    <collision>
      <origin rpy="0 0 0" xyz="0 0 0"/>
      <geometry>
        <box size="1.0 0.05 1.4"/>
      </geometry>
    </collision>
  </link>
  <joint name="frame_right_joint" type="fixed">
    <origin rpy="0 0 1.57079632679" xyz="0.725 -0.475 0"/>
    <parent link="frame_back_wall"/>
    <child link="frame_right_wall"/>
  </joint>
  <link name="frame_top_wall">
    <contact>
      <lateral_friction value="1.0"/>
    </contact>
    <inertial>
      <origin rpy="0 0 0" xyz="0 0 0"/>
      <mass value="0.2"/>
      <inertia ixx="1" ixy="0" ixz="0" iyy="1" iyz="0" izz="1"/>
    </inertial>
    <visual>
      <origin rpy="0 0 0" xyz="0 0 0"/>
      <geometry>
        <box size="1.5 0.05 1.0"/>
      </geometry>
      <material name="white">
        <color rgba="1 1 1 1"/>
      </material>
    </visual>
    <collision>
      <origin rpy="0 0 0" xyz="0 0 0"/>
      <geometry>
        <box size="1.5 0.05 1.0"/>
      </geometry>
    </collision>
  </link>
  <joint name="frame_top_joint" type="fixed">
    <origin rpy="1.57079632679 0 0" xyz="0 -0.475 0.725"/>
    <parent link="frame_back_wall"/>
    <child link="frame_top_wall"/>
  </joint>
  <joint name="frame_joint" type="fixed">
    <origin rpy="0 0 0" xyz="0 0.475 0.75"/>
    <parent link="base_link"/>
    <child link="frame_back_wall"/>
  </joint>
  <!-- <xacro:drawer index="1"/>
<xacro:drawer index="2"/>
<xacro:drawer index="3"/> -->
  <link name="drawer1_back_wall">
    <contact>
      <lateral_friction value="1.0"/>
    </contact>
    <inertial>
      <origin rpy="0 0 0" xyz="0 0 0"/>
      <mass value="0.2"/>
      <inertia ixx="1" ixy="0" ixz="0" iyy="1" iyz="0" izz="1"/>
    </inertial>
    <visual>
      <origin rpy="0 0 0" xyz="0 0 0"/>
      <geometry>
        <box size="1.34 0.025 0.895"/>
      </geometry>
      <material name="white">
        <color rgba="1 1 1 1"/>
      </material>
    </visual>
    <collision>
      <origin rpy="0 0 0" xyz="0 0 0"/>
      <geometry>
        <box size="1.34 0.025 0.895"/>
      </geometry>
    </collision>
  </link>
  <link name="drawer1_bottom_wall">
    <contact>
      <lateral_friction value="1.0"/>
    </contact>
    <inertial>
      <origin rpy="0 0 0" xyz="0 0 0"/>
      <mass value="0.2"/>
      <inertia ixx="1" ixy="0" ixz="0" iyy="1" iyz="0" izz="1"/>
    </inertial>
    <visual>
      <origin rpy="0 0 0" xyz="0 0 0"/>
      <geometry>
        <box size="1.39 0.025 0.46"/>
      </geometry>
      <material name="white">
        <color rgba="1 1 1 1"/>
      </material>
    </visual>
    <collision>
      <origin rpy="0 0 0" xyz="0 0 0"/>
      <geometry>
        <box size="1.39 0.025 0.46"/>
      </geometry>
    </collision>
  </link>
  <joint name="drawer1_bottom_joint" type="fixed">
    <origin rpy="1.57079632679 0 0" xyz="0 -0.2175 -0.46"/>
    <parent link="drawer1_back_wall"/>
    <child link="drawer1_bottom_wall"/>
  </joint>
  <link name="drawer1_left_wall">
    <contact>
      <lateral_friction value="1.0"/>
    </contact>
    <inertial>
      <origin rpy="0 0 0" xyz="0 0 0"/>
      <mass value="0.2"/>
      <inertia ixx="1" ixy="0" ixz="0" iyy="1" iyz="0" izz="1"/>
    </inertial>
    <visual>
      <origin rpy="0 0 0" xyz="0 0 0"/>
      <geometry>
        <box size="0.46 0.025 0.895"/>
      </geometry>
      <material name="white">
        <color rgba="1 1 1 1"/>
      </material>
    </visual>
    <collision>
      <origin rpy="0 0 0" xyz="0 0 0"/>
      <geometry>
        <box size="0.46 0.025 0.895"/>
      </geometry>
    </collision>
  </link>
  <joint name="drawer1_left_joint" type="fixed">
    <origin rpy="0 0 1.57079632679" xyz="-0.6825 -0.2175 0"/>
    <parent link="drawer1_back_wall"/>
    <child link="drawer1_left_wall"/>
  </joint>
  <link name="drawer1_right_wall">
    <contact>
      <lateral_friction value="1.0"/>
    </contact>
    <inertial>
      <origin rpy="0 0 0" xyz="0 0 0"/>
      <mass value="0.2"/>
      <inertia ixx="1" ixy="0" ixz="0" iyy="1" iyz="0" izz="1"/>
    </inertial>
    <visual>
      <origin rpy="0 0 0" xyz="0 0 0"/>
      <geometry>
        <box size="0.46 0.025 0.895"/>
      </geometry>
      <material name="white">
        <color rgba="1 1 1 1"/>
      </material>
    </visual>
    <collision>
      <origin rpy="0 0 0" xyz="0 0 0"/>
      <geometry>
        <box size="0.46 0.025 0.895"/>
      </geometry>
    </collision>
  </link>
  <joint name="drawer1_right_joint" type="fixed">
    <origin rpy="0 0 1.57079632679" xyz="0.6825 -0.2175 0"/>
    <parent link="drawer1_back_wall"/>
    <child link="drawer1_right_wall"/>
  </joint>
  <link name="drawer1_top_wall">
    <contact>
      <lateral_friction value="1.0"/>
    </contact>
    <inertial>
      <origin rpy="0 0 0" xyz="0 0 0"/>
      <mass value="0.2"/>
      <inertia ixx="1" ixy="0" ixz="0" iyy="1" iyz="0" izz="1"/>
    </inertial>
    <visual>
      <origin rpy="0 0 0" xyz="0 0 0"/>
      <geometry>
        <box size="1.39 0.025 0.46"/>
      </geometry>
      <material name="white">
        <color rgba="1 1 1 1"/>
      </material>
    </visual>
    <collision>
      <origin rpy="0 0 0" xyz="0 0 0"/>
      <geometry>
        <box size="1.39 0.025 0.46"/>
      </geometry>
    </collision>
  </link>
  <joint name="drawer1_top_joint" type="fixed">
    <origin rpy="1.57079632679 0 0" xyz="0 -0.2175 0.46"/>
    <parent link="drawer1_back_wall"/>
    <child link="drawer1_top_wall"/>
  </joint>
  <joint name="drawer1_joint" type="prismatic">
    <origin rpy="-1.57079632679 0 0" xyz="0 -0.0275 1.7"/>
    <parent link="base_link"/>
    <child link="drawer1_back_wall"/>
    <axis xyz="0 0 -1"/>
    <dynamics damping="0.0"/>
    <limit effort="1.0" lower="-10.0" upper="10.5" velocity="1.5"/>
  </joint>
</robot>

